Workbook

Sheet Info
A1: You work for an Accounting Firm as a Bookkeeper and you're manager has came to you with a new client;
A2: Miss Jones.
A4: Part A:
A5: Update Miss Jone's Daybooks from the list of transactions provided below:
A7: Part B:
A8: Transfer the Daybooks into the Ledger Accounts: Sales Ledger, Purchase Ledger,
A9: and General Ledger, then produce a Trial Balance.
A11: Part C:
A12: Produce a VAT Return for Miss Jones.
A14: Transactions to be Recorded:
A16: 46174 | B16: Miss Jone's has injected £100,000 in bank and £8,000 of cash into her business as capital.
A17: 45809 | B17: Bought goods for resale from Ladies Ltd on credit for £2,750 which in inclusive of VAT. They offer a prompt payment discount of 2% if paid within 28 days.
A18: 45809 | B18: Bought goods for resale on credit from D n A Partners. for £3,200 Gross.
A19: 45810 | B19: Bought office equipment for £5,000 including VAT paying by debit card through the bank.
A20: 45812 | B20: Paid monthly rent and rates of £1,850 via bacs transfer - this is exempt from VAT.
A21: 45813 | B21: Received an invoice for purchase of inventory from D n A Partners. for £3,500 (zero VAT).
A22: 45813 | B22: Sold goods on credit to David and Sons plc for £5,600 Gross.
A23: 45815 | B23: Cash sales of £1,800 inclusive of VAT.
A24: 45816 | B24: Paid telephone of £154.00 Gross by cash
A25: 45820 | B25: Sold goods to Rainbow Plc on credit for £5,000 net. Prompt payment discount of 3% if paid with 28 days.
A26: 45822 | B26: Returned goods to D n A Partners. and received a credit note for £820 inclusive of VAT.
A27: 45823 | B27: Purchased a car from Cars and Vans for £22,000 including VAT paid by bacs transfer. He will be using this solely for business purposes.
... A38: 45838 | B38: Received £1,500 in cash from David and Sons as a part payment of the balance due.

Sheet Part A
B2: Part of the Sales Ledger | H2: Part of the Purchase Ledger | N2: Part of the General Ledger
B4: Sales Day Book | D4: DR | E4: CR | F4: CR | H4: Purchase Day Book | J4: CR | K4: DR | L4: DR | N4: Cash Book Lodged | P4: Cr | Q4: =P4 -> Cr | R4: =Q4 -> Cr | S4: =R4 -> Cr | T4: =S4 -> Cr | U4: =T4 -> Cr
B5: Date | C5: Name of Customer | D5: Gross | E5: VAT | F5: Net | H5: Date | I5: Name of Supplier | J5: Gross | K5: VAT | L5: Net | N5: Date | O5: Details | P5: Bank | Q5: Cash | R5: VAT | S5: Receipts Customers | T5: Capital | U5: Net Sales
D6: £ | E6: £ | F6: £ | J6: £ | K6: £ | L6: £ | N6: 46174 | O6: Capital | P6: 100000 | Q6: 8000 | T6: =P6+Q6 -> 108000
B7: 46178 | C7: David and Sons Plc | D7: 5600 | E7: =D7/6 -> 933.33333 | F7: =D7-E7 -> 4666.6667 | H7: 46174 | I7: Ladies Ltd | J7: 2750 | K7: =J7/6 -> 458.33333 | L7: =J7-K7 -> 2291.6667 | N7: 46180 | O7: Cash Sales | Q7: 1800 | R7: =Q7/6 -> 300 | U7: =Q7-R7 -> 1500
B8: 46185 | C8: Rainbow Plc | D8: =E8+F8 -> 6000 | E8: =F8*0.2 -> 1000 | F8: 5000 | H8: 46174 | I8: DNA Partners | J8: 3200 | K8: =J8/6 -> 533.33333 | L8: =J8-K8 -> 2666.6667 | N8: 46193 | O8: Cash Sales | Q8: 1000 | R8: - | U8: =Q8 -> 1000
B9: 46197 | C9: Rainbow Plc | D9: =E9+F9 -> 4800 | E9: =F9*0.2 -> 800 | F9: 4000 | H9: 46178 | I9: DNA Partners | J9: 3500 | K9: - | L9: =J9 -> 3500 | N9: 46201 | O9: Rainbow Plc | P9: =C41 -> 9312 | S9: =P9 -> 9312
B10: 46197 | C10: David and Sons Plc | D10: 6000 | E10: =D10/6 -> 1000 | F10: =D10-E10 -> 5000 | H10: 46200 | I10: Ladies Ltd | J10: 2600 | K10: =J10/6 -> 433.33333 | L10: =J10-K10 -> 2166.6667 | N10: 46203 | O10: David and Sons | Q10: 1500 | S10: =Q10 -> 1500
D12: =SUM(D7:D11) -> 22400 | E12: =SUM(E7:E11) -> 3733.3333 | F12: =SUM(F7:F11) -> 18666.667 | J12: =SUM(J7:J11) -> 12050 | K12: =SUM(K7:K11) -> 1425 | L12: =SUM(L7:L11) -> 10625 | P12: =SUM(P6:P10) -> 109312 | Q12: =SUM(Q6:Q10) -> 12300 | R12: =SUM(R6:R10) -> 300 | S12: =SUM(S6:S10) -> 10812 | T12: =SUM(T6:T10) -> 108000 | U12: =SUM(U6:U10) -> 2500
B14: Sales Return Day Book | D14: CR | E14: DR | F14: DR | H14: Purchase Return Day Book | J14: DR | K14: CR | L14: CR | O14: Balance B/D | P14: =P26 -> 75267 | Q14: =Q26 -> 12095
B15: =B5 -> Date | C15: Name of Customer | D15: =D5 -> Gross | E15: =E5 -> VAT | F15: =F5 -> Net | H15: =H5 -> Date | I15: Name of Supplier | J15: =J5 -> Gross | K15: =K5 -> VAT | L15: =L5 -> Net
D16: £ | E16: £ | F16: £ | J16: £ | K16: £ | L16: £ | N16: Cash Book Drawn | P16: Dr | Q16: =P16 -> Dr | R16: =Q16 -> Dr | S16: =R16 -> Dr | T16: =S16 -> Dr | U16: =T16 -> Dr | V16: =U16 -> Dr | W16: =V16 -> Dr | X16: =W16 -> Dr
B17: 46199 | C17: Rainbow Plc | D17: =E17+F17 -> 1200 | E17: =F17*0.2 -> 200 | F17: 1000 | H17: 46187 | I17: DNA Partners | J17: 820 | K17: =J17/6 -> 136.66667 | L17: =J17-K17 -> 683.33333 | N17: Date | O17: Details | P17: Bank | Q17: Cash | R17: VAT | S17: Payments Suppliers | T17: Office Equipment | U17: Phone | V17: Rent & Rates | W17: Net Motors | X17: Postage
B18: 46201 | C18: David and Sons Plc | D18: 800 | E18: =D18/6 -> 133.33333 | F18: =D18-E18 -> 666.66667 | N18: 46175 | O18: Office Equipment | P18: 5000 | R18: =P18/6 -> 833.33333 | T18: =P18-R18 -> 4166.6667
N19: 46177 | O19: Rent and Rates | P19: =1850 -> 1850 | R19: EXEMPT | V19: =P19 -> 1850
D20: =SUM(D17:D19) -> 2000 | E20: =SUM(E17:E19) -> 333.33333 | F20: =SUM(F17:F19) -> 1666.6667 | J20: =SUM(J17:J19) -> 820 | K20: =SUM(K17:K19) -> 136.66667 | L20: =SUM(L17:L19) -> 683.33333 | N20: 46181 | O20: Telephone | Q20: 154 | R20: =Q20/6 -> 25.666667 | U20: =Q20-R20 -> 128.33333
N21: 46188 | O21: Cars and Vans | P21: 22000 | R21: =P21/6 -> 3666.6667 | W21: =P21-R21 -> 18333.333
B22: Discount Allowed | D22: CR | E22: DR | F22: DR | H22: Discount Received | J22: DR | K22: CR | L22: CR | N22: 46194 | O22: Postage | Q22: 51 | R22: EXEMPT | X22: =Q22 -> 51
B23: Date | C23: Name of Customer | D23: Gross | E23: VAT | F23: Net | H23: Date | I23: Name of Supplier | J23: Gross | K23: VAT | L23: Net | N23: 46197 | O23: DNA Partners | P23: 2500 | S23: =P23 -> 2500
D24: £ | E24: £ | F24: £ | J24: £ | K24: £ | L24: £ | N24: 46199 | O24: Ladies Ltd | P24: =C33 -> 2695 | S24: =P24 -> 2695
B25: 46201 | C25: Rainbow Plc | D25: =C40 -> 288 | E25: =D25/6 -> 48 | F25: =D25-E25 -> 240 | H25: 46199 | I25: Ladies Ltd | J25: =C32 -> 55 | K25: =J25/6 -> 9.1666667 | L25: =J25-K25 -> 45.833333
N26: 46203 | O26: Balance C/D | P26: =P12-SUM(P18:P24) -> 75267 | Q26: =Q12-SUM(Q18:Q24) -> 12095
D28: =SUM(D25:D27) -> 288 | E28: =SUM(E25:E27) -> 48 | F28: =SUM(F25:F27) -> 240 | J28: =SUM(J25:J27) -> 55 | K28: =SUM(K25:K27) -> 9.1666667 | L28: =SUM(L25:L27) -> 45.833333 | P28: =SUM(P18:P26) -> 109312 | Q28: =SUM(Q18:Q26) -> 12300 | R28: =SUM(R18:R26) -> 4525.6667 | S28: =SUM(S18:S26) -> 5195 | T28: =SUM(T18:T26) -> 4166.6667 | U28: =SUM(U18:U26) -> 128.33333 | V28: =SUM(V18:V26) -> 1850 | W28: =SUM(W18:W26) -> 18333.333 | X28: =SUM(X18:X26) -> 51
C30: Ladies Ltd | D30: (Supplier)
B31: =H7 -> 46174 | C31: =J7 -> 2750 | D31: 1st Invoice
B32: PAY | C32: =C31*0.02 -> 55 | D32: Less Discount
B33: PAY | C33: =C31-C32 -> 2695 | D33: Payable
C35: Rainbow Plc | D35: (Customer)
B36: =B8 -> 46185 | C36: =D8 -> 6000 | D36: 1st Invoice
B37: =B9 -> 46197 | C37: =D9 -> 4800 | D37: 2nd Invoice
B38: =B17 -> 46199 | C38: =D17 -> 1200 | D38: Less Return
C39: =(C36+C37)-C38 -> 9600 | D39: Total
B40: PAY | C40: =C39*0.03 -> 288 | D40: Less Discount
B41: PAY | C41: =C39-C40 -> 9312 | D41: Payable

Sheet Part B
B2: Sales Ledger | I2: Miss Jones
I3: Trial Balance
B4: Account: | C4: David and Sons | J4: DR £ | K4: CR £
B5: Date | C5: Details | D5: Debit | E5: Credit | F5: Balance | I5: Cash | J5: ='Part A'!Q14 -> 12095
D6: £ | E6: £ | F6: £ | I6: Bank | J6: ='Part A'!P14 -> 75267
B7: ='Part A'!B7 -> 46178 | C7: ='Part A'!B4 -> Sales Day Book | D7: ='Part A'!D7 -> 5600 | F7: =D7 -> 5600 | G7: DR | I7: =C4 -> David and Sons | J7: =F10 -> 9300
B8: ='Part A'!B10 -> 46197 | C8: =C7 -> Sales Day Book | D8: ='Part A'!D10 -> 6000 | F8: =F7+D8 -> 11600 | G8: DR | I8: =C12 -> Rainbow Plc | J8: =F19 -> 0
B9: ='Part A'!B18 -> 46201 | C9: ='Part A'!B14 -> Sales Return Day Book | E9: ='Part A'!D18 -> 800 | F9: =F8-E9 -> 10800 | G9: DR | I9: =C23 -> Ladies Ltd | K9: =F29 -> 2600
B10: 45838 | C10: Cash Book Lodged (Receipts) | E10: ='Part A'!S10 -> 1500 | F10: =F9-E10 -> 9300 | G10: DR | I10: =C31 -> DNA Partners | K10: =F37 -> 3380
I11: =C41 -> VAT | J11: =F51 -> 2152.8333
B12: Account: | C12: Rainbow Plc | I12: =C53 -> Sales | K12: =F57 -> 21166.667
B13: Date | C13: Details | D13: Debit | E13: Credit | F13: Balance | I13: =C59 -> Sales Returns | J13: =F62 -> 1666.6667
D14: £ | E14: £ | F14: £ | I14: =C64 -> Discount Allowed | J14: =F67 -> 240
B15: ='Part A'!B8 -> 46185 | C15: ='Part A'!B4 -> Sales Day Book | D15: ='Part A'!D8 -> 6000 | F15: =D15 -> 6000 | G15: DR | I15: =C69 -> Purchases | J15: =F72 -> 10625
B16: ='Part A'!B9 -> 46197 | C16: =C15 -> Sales Day Book | D16: ='Part A'!D9 -> 4800 | F16: =F15+D16 -> 10800 | G16: DR | I16: =C74 -> Purchase Returns | K16: =F77 -> 683.33333
B17: ='Part A'!B17 -> 46199 | C17: ='Part A'!B14 -> Sales Return Day Book | E17: ='Part A'!D17 -> 1200 | F17: =F16-E17 -> 9600 | G17: DR | I17: =C79 -> Discount Received | K17: =F82 -> 45.833333
B18: ='Part A'!B25 -> 46201 | C18: ='Part A'!B22 -> Discount Allowed | E18: ='Part A'!D25 -> 288 | F18: =F17-E18 -> 9312 | G18: DR | I18: =C84 -> Capital | K18: =F87 -> 108000
B19: 45838 | C19: Cash Book Lodged (Receipts) | E19: ='Part A'!S9 -> 9312 | F19: =F18-E19 -> 0 | G19: DR | I19: =C89 -> Office Equipment | J19: =F92 -> 4166.6667
I20: =C94 -> Phone | J20: =F97 -> 128.33333
B21: Purchase Ledger | I21: =C99 -> Rent and Rates | J21: =F102 -> 1850
I22: =C104 -> Motor Vehicle | J22: =F107 -> 18333.333
B23: Account: | C23: Ladies Ltd | I23: =C109 -> Postage | J23: =F112 -> 51
B24: Date | C24: Details | D24: Debit | E24: Credit | F24: Balance
D25: £ | E25: £ | F25: £ | J25: =SUM(J5:J23) -> 135875.83 | K25: =SUM(K5:K23) -> 135875.83
B26: ='Part A'!H7 -> 46174 | C26: ='Part A'!H4 -> Purchase Day Book | E26: ='Part A'!J7 -> 2750 | F26: =E26 -> 2750 | G26: CR
B27: ='Part A'!H25 -> 46199 | C27: ='Part A'!H22 -> Discount Received | D27: ='Part A'!J25 -> 55 | F27: =F26-D27 -> 2695 | G27: CR | I27: Difference: | J27: =J25-K25 -> 0
B28: ='Part A'!H10 -> 46200 | C28: =C26 -> Purchase Day Book | E28: ='Part A'!J10 -> 2600 | F28: =F27+E28 -> 5295 | G28: CR
B29: 45838 | C29: Cash Book Drawn (Payments) | D29: ='Part A'!S24 -> 2695 | F29: =F28-D29 -> 2600 | G29: CR
B31: Account: | C31: DNA Partners
B32: Date | C32: Details | D32: Debit | E32: Credit | F32: Balance
D33: £ | E33: £ | F33: £
B34: ='Part A'!H8 -> 46174 | C34: ='Part A'!H4 -> Purchase Day Book | E34: ='Part A'!J8 -> 3200 | F34: =E34 -> 3200 | G34: CR
B35: ='Part A'!H9 -> 46178 | C35: =C34 -> Purchase Day Book | E35: ='Part A'!J9 -> 3500 | F35: =F34+E35 -> 6700 | G35: CR
B36: ='Part A'!H17 -> 46187 | C36: ='Part A'!H14 -> Purchase Return Day Book | D36: ='Part A'!J17 -> 820 | F36: =F35-D36 -> 5880 | G36: CR
B37: 45838 | C37: Cash Book Drawn (Payments) | D37: ='Part A'!S23 -> 2500 | F37: =F36-D37 -> 3380 | G37: CR
B39: General Ledger
B41: Account: | C41: VAT
B42: Date | C42: Details | D42: Debit | E42: Credit | F42: Balance
D43: £ | E43: £ | F43: £
B44: 45838 | C44: Sales Day Book | E44: ='Part A'!E12 -> 3733.3333 | F44: =E44 -> 3733.3333 | G44: CR
...

Sheet Part C
A1: VAT Return
A4: There are nine sections regarding VAT, and they are:
A6: VAT due in this period of sales and other outputs | L6: 1 | M6: =D24 -> 3652
A7: VAT due in this period on acquisitions from other EC member states. | L7: 2
A8: Total VAT due (i.e., 1 + 2). | L8: 3 | M8: =M6+M7 -> 3652
A9: VAT reclaimed in this period on purchases and other inputs (incl. acquisitions from the EC). | L9: 4 | M9: =D32 -> 5804.8333
A10: Net VAT to be paid to customs or reclaimed by you (Difference between 3 and 4). | L10: 5 | M10: =M8-M9 -> -2152.8333 | N10: minus means we get to reclaim this amount, normal means we need to pay that.
A11: Total value of sales and all other outputs excluding any VAT, include box 8 figures. | L11: 6 | M11: =E24 -> 19260
A12: Total value of purchases and all other inputs excluding any VAT, include box 9 figures. | L12: 7 | M12: =E32 -> 34425.167
A13: Total value of all supplies of goods and related services excluding any VAT, to other member states. | L13: 8 | M13: N/A
A14: Total value of all acquisition of goods and related services excluding any VAT, from other EC member states. | L14: 9 | M14: =M13 -> N/A
A16: We get these from the accounts within the ledgers:
D18: Output VAT | E18: Value of Output
D19: Box 1 & 3 | E19: Box 6
A20: Sales Day Book | D20: ='Part A'!E12 -> 3733.3333 | E20: ='Part A'!F12 -> 18666.667
A21: Sales Return Day Book | D21: ='Part A'!E20 -> 333.33333 | E21: ='Part A'!F20 -> 1666.6667
A22: Discount Allowed Day Book | D22: ='Part A'!E28 -> 48 | E22: ='Part A'!F28 -> 240
A23: Cash Book Lodged (Receipts) | D23: ='Part A'!R12 -> 300 | E23: ='Part A'!U12 -> 2500
C24: Total: | D24: =D20-D21-D22+D23 -> 3652 | E24: =E20-E21-E22+E23 -> 19260
D26: Input VAT | E26: Value of Input
D27: Box 4 | E27: Box 7
A28: Purchase Day Book | D28: ='Part A'!K12 -> 1425 | E28: ='Part A'!L12 -> 10625
A29: Purchase Return Day Book | D29: ='Part A'!K20 -> 136.66667 | E29: ='Part A'!L20 -> 683.33333
A30: Discount Received Day Book | D30: ='Part A'!K28 -> 9.1666667 | E30: ='Part A'!L28 -> 45.833333
A31: Cash Book Drawn (Payments) | D31: ='Part A'!R28 -> 4525.6667 | E31: =SUM('Part A'!T28:X28) -> 24529.333
C32: Total: | D32: =D28-D29-D30+D31 -> 5804.8333 | E32: =E28-E29-E30+E31 -> 34425.167
A34: *the output/input VAT is the VAT amounts on the accounts here.
A35: *the value of output/inout is the Net amounts on the accounts here.
